Traceback (most recent call last):
  File "/home/ubuntu/CatDB/Experiments/setup/Baselines/CatDB/runcode/RunCode.py", line 36, in execute_code
    exec(compile(parse, filename="<ast>", mode="exec"), loc)
  File "<ast>", line 55, in <module>
  File "/home/ubuntu/CatDB/Experiments/setup/Baselines/CatDB/venv/lib/python3.11/site-packages/sklearn/ensemble/_forest.py", line 1064, in predict
    X = self._validate_X_predict(X)
        ^^^^^^^^^^^^^^^^^^^^^^^^^^^
  File "/home/ubuntu/CatDB/Experiments/setup/Baselines/CatDB/venv/lib/python3.11/site-packages/sklearn/ensemble/_forest.py", line 641, in _validate_X_predict
    X = self._validate_data(
        ^^^^^^^^^^^^^^^^^^^^
  File "/home/ubuntu/CatDB/Experiments/setup/Baselines/CatDB/venv/lib/python3.11/site-packages/sklearn/base.py", line 608, in _validate_data
    self._check_feature_names(X, reset=reset)
  File "/home/ubuntu/CatDB/Experiments/setup/Baselines/CatDB/venv/lib/python3.11/site-packages/sklearn/base.py", line 535, in _check_feature_names
    raise ValueError(message)
ValueError: The feature names should match those that were passed during fit.
Feature names unseen at fit time:
- 114_0.3333333333333333
- 56_0.8888888888888888
- 75_0.8888888888888888
- 79_0.8888888888888888
Feature names seen at fit time, yet now missing:
- 109_0.7777777777777777
- 113_0.2222222222222222
- 113_0.3333333333333333
- 113_0.4444444444444444
- 113_0.5555555555555556
- ...

