Traceback (most recent call last):
  File "/home/ubuntu/CatDB/Experiments/setup/Baselines/CatDB/venv/lib/python3.11/site-packages/sklearn/utils/_encode.py", line 225, in _encode
    return _map_to_integer(values, uniques)
           ^^^^^^^^^^^^^^^^^^^^^^^^^^^^^^^^
  File "/home/ubuntu/CatDB/Experiments/setup/Baselines/CatDB/venv/lib/python3.11/site-packages/sklearn/utils/_encode.py", line 165, in _map_to_integer
    return np.array([table[v] for v in values])
                    ^^^^^^^^^^^^^^^^^^^^^^^^^^
  File "/home/ubuntu/CatDB/Experiments/setup/Baselines/CatDB/venv/lib/python3.11/site-packages/sklearn/utils/_encode.py", line 165, in <listcomp>
    return np.array([table[v] for v in values])
                     ~~~~~^^^
  File "/home/ubuntu/CatDB/Experiments/setup/Baselines/CatDB/venv/lib/python3.11/site-packages/sklearn/utils/_encode.py", line 159, in __missing__
    raise KeyError(key)
KeyError: '<unknown>'

During handling of the above exception, another exception occurred:

Traceback (most recent call last):
  File "/home/ubuntu/CatDB/Experiments/setup/Baselines/CatDB/runcode/RunCode.py", line 36, in execute_code
    exec(compile(parse, filename="<ast>", mode="exec"), loc)
  File "<ast>", line 40, in <module>
  File "/home/ubuntu/CatDB/Experiments/setup/Baselines/CatDB/venv/lib/python3.11/site-packages/sklearn/preprocessing/_label.py", line 137, in transform
    return _encode(y, uniques=self.classes_)
           ^^^^^^^^^^^^^^^^^^^^^^^^^^^^^^^^^
  File "/home/ubuntu/CatDB/Experiments/setup/Baselines/CatDB/venv/lib/python3.11/site-packages/sklearn/utils/_encode.py", line 227, in _encode
    raise ValueError(f"y contains previously unseen labels: {str(e)}")
ValueError: y contains previously unseen labels: '<unknown>'
