Traceback (most recent call last):
  File "/home/ubuntu/CatDB/Experiments/catdb-results/dataset_1_rnc/gpt-4/dataset_1_rnc-SCHEMA-Random-0-SHOT-gpt-4.py", line 47, in <module>
    y_pred = clf.predict(X_test)
             ^^^^^^^^^^^^^^^^^^^
  File "/home/ubuntu/CatDB/Experiments/catdb-results/dataset_1_rnc/gpt-4/venv/lib/python3.11/site-packages/sklearn/ensemble/_forest.py", line 905, in predict
    proba = self.predict_proba(X)
            ^^^^^^^^^^^^^^^^^^^^^
  File "/home/ubuntu/CatDB/Experiments/catdb-results/dataset_1_rnc/gpt-4/venv/lib/python3.11/site-packages/sklearn/ensemble/_forest.py", line 947, in predict_proba
    X = self._validate_X_predict(X)
        ^^^^^^^^^^^^^^^^^^^^^^^^^^^
  File "/home/ubuntu/CatDB/Experiments/catdb-results/dataset_1_rnc/gpt-4/venv/lib/python3.11/site-packages/sklearn/ensemble/_forest.py", line 641, in _validate_X_predict
    X = self._validate_data(
        ^^^^^^^^^^^^^^^^^^^^
  File "/home/ubuntu/CatDB/Experiments/catdb-results/dataset_1_rnc/gpt-4/venv/lib/python3.11/site-packages/sklearn/base.py", line 608, in _validate_data
    self._check_feature_names(X, reset=reset)
  File "/home/ubuntu/CatDB/Experiments/catdb-results/dataset_1_rnc/gpt-4/venv/lib/python3.11/site-packages/sklearn/base.py", line 535, in _check_feature_names
    raise ValueError(message)
ValueError: The feature names should match those that were passed during fit.
Feature names unseen at fit time:
- c_27

