Traceback (most recent call last):
  File "/home/ubuntu/CatDB/Experiments/catdb-results/dataset_1_rnc/gpt-4/dataset_1_rnc-DISTINCT-Random-0-SHOT-gpt-4.py", line 33, in <module>
    train_data.drop(columns=['c_27'], inplace=True)
  File "/home/ubuntu/CatDB/Experiments/catdb-results/dataset_1_rnc/gpt-4/venv/lib/python3.11/site-packages/pandas/core/frame.py", line 5568, in drop
    return super().drop(
           ^^^^^^^^^^^^^
  File "/home/ubuntu/CatDB/Experiments/catdb-results/dataset_1_rnc/gpt-4/venv/lib/python3.11/site-packages/pandas/core/generic.py", line 4782, in drop
    obj = obj._drop_axis(labels, axis, level=level, errors=errors)
          ^^^^^^^^^^^^^^^^^^^^^^^^^^^^^^^^^^^^^^^^^^^^^^^^^^^^^^^^
  File "/home/ubuntu/CatDB/Experiments/catdb-results/dataset_1_rnc/gpt-4/venv/lib/python3.11/site-packages/pandas/core/generic.py", line 4824, in _drop_axis
    new_axis = axis.drop(labels, errors=errors)
               ^^^^^^^^^^^^^^^^^^^^^^^^^^^^^^^^
  File "/home/ubuntu/CatDB/Experiments/catdb-results/dataset_1_rnc/gpt-4/venv/lib/python3.11/site-packages/pandas/core/indexes/base.py", line 7069, in drop
    raise KeyError(f"{labels[mask].tolist()} not found in axis")
KeyError: "['c_27'] not found in axis"
