Traceback (most recent call last):
  File "/home/ubuntu/CatDB/Experiments/setup/Baselines/CatDB/runcode/RunCode.py", line 36, in execute_code
    exec(compile(parse, filename="<ast>", mode="exec"), loc)
  File "<ast>", line 45, in <module>
  File "/home/ubuntu/CatDB/Experiments/setup/Baselines/CatDB/venv/lib/python3.11/site-packages/sklearn/utils/_set_output.py", line 295, in wrapped
    data_to_wrap = f(self, X, *args, **kwargs)
                   ^^^^^^^^^^^^^^^^^^^^^^^^^^^
  File "/home/ubuntu/CatDB/Experiments/setup/Baselines/CatDB/venv/lib/python3.11/site-packages/sklearn/preprocessing/_encoders.py", line 1023, in transform
    X_int, X_mask = self._transform(
                    ^^^^^^^^^^^^^^^^
  File "/home/ubuntu/CatDB/Experiments/setup/Baselines/CatDB/venv/lib/python3.11/site-packages/sklearn/preprocessing/_encoders.py", line 213, in _transform
    raise ValueError(msg)
ValueError: Found unknown categories ['(232, 176, 244)', '(247, 149, 140)', '(53, 158, 165)', '(120, 168, 37)', '(136, 226, 122)', '(43, 216, 147)', '(219, 255, 158)', '(172, 154, 226)', '(218, 239, 79)', '(237, 169, 168)', '(237, 171, 158)', '(162, 221, 95)', '(138, 203, 226)', '(255, 99, 200)', '(252, 242, 166)', '(72, 173, 13)', '(39, 132, 145)', '(51, 61, 150)', '(88, 219, 81)', '(239, 170, 184)', '(92, 4, 209)', '(197, 188, 244)', '(229, 6, 51)', '(247, 131, 148)', '(146, 239, 192)', '(249, 179, 14)', '(249, 192, 194)', '(66, 112, 181)', '(242, 58, 144)', '(13, 85, 130)', '(135, 89, 204)', '(244, 80, 236)', '(198, 4, 247)', '(49, 90, 165)', '(221, 106, 108)', '(157, 141, 239)', '(206, 255, 173)', '(129, 239, 177)', '(221, 2, 203)', '(214, 42, 62)', '(197, 20, 206)', '(184, 140, 234)', '(220, 162, 239)', '(164, 249, 210)', '(95, 203, 239)', '(121, 102, 214)', '(211, 198, 21)', '(252, 212, 191)', '(216, 191, 78)', '(125, 211, 40)', '(102, 188, 214)', '(242, 180, 109)', '(226, 108, 164)', '(211, 80, 165)', '(242, 119, 62)'] in column 17 during transform
