Traceback (most recent call last):
  File "/home/ubuntu/CatDB/Experiments/setup/Baselines/CatDB/runcode/RunCode.py", line 36, in execute_code
    exec(compile(parse, filename="<ast>", mode="exec"), loc)
  File "<ast>", line 11, in <module>
  File "/home/ubuntu/CatDB/Experiments/setup/Baselines/CatDB/venv/lib/python3.11/site-packages/pandas/io/parsers/readers.py", line 948, in read_csv
    return _read(filepath_or_buffer, kwds)
           ^^^^^^^^^^^^^^^^^^^^^^^^^^^^^^^
  File "/home/ubuntu/CatDB/Experiments/setup/Baselines/CatDB/venv/lib/python3.11/site-packages/pandas/io/parsers/readers.py", line 611, in _read
    parser = TextFileReader(filepath_or_buffer, **kwds)
             ^^^^^^^^^^^^^^^^^^^^^^^^^^^^^^^^^^^^^^^^^^
  File "/home/ubuntu/CatDB/Experiments/setup/Baselines/CatDB/venv/lib/python3.11/site-packages/pandas/io/parsers/readers.py", line 1448, in __init__
    self._engine = self._make_engine(f, self.engine)
                   ^^^^^^^^^^^^^^^^^^^^^^^^^^^^^^^^^
  File "/home/ubuntu/CatDB/Experiments/setup/Baselines/CatDB/venv/lib/python3.11/site-packages/pandas/io/parsers/readers.py", line 1705, in _make_engine
    self.handles = get_handle(
                   ^^^^^^^^^^^
  File "/home/ubuntu/CatDB/Experiments/setup/Baselines/CatDB/venv/lib/python3.11/site-packages/pandas/io/common.py", line 863, in get_handle
    handle = open(
             ^^^^^
FileNotFoundError: [Errno 2] No such file or directory: 'correct_path_to_train_data'
