Traceback (most recent call last):
  File "/home/ubuntu/CatDB/Experiments/catdb-results/dataset_2_rnc/gpt-4/venv/lib/python3.11/site-packages/sklearn/utils/_encode.py", line 225, in _encode
    return _map_to_integer(values, uniques)
           ^^^^^^^^^^^^^^^^^^^^^^^^^^^^^^^^
  File "/home/ubuntu/CatDB/Experiments/catdb-results/dataset_2_rnc/gpt-4/venv/lib/python3.11/site-packages/sklearn/utils/_encode.py", line 165, in _map_to_integer
    return np.array([table[v] for v in values])
                    ^^^^^^^^^^^^^^^^^^^^^^^^^^
  File "/home/ubuntu/CatDB/Experiments/catdb-results/dataset_2_rnc/gpt-4/venv/lib/python3.11/site-packages/sklearn/utils/_encode.py", line 165, in <listcomp>
    return np.array([table[v] for v in values])
                     ~~~~~^^^
  File "/home/ubuntu/CatDB/Experiments/catdb-results/dataset_2_rnc/gpt-4/venv/lib/python3.11/site-packages/sklearn/utils/_encode.py", line 159, in __missing__
    raise KeyError(key)
KeyError: "'<0'"

During handling of the above exception, another exception occurred:

Traceback (most recent call last):
  File "/home/ubuntu/CatDB/Experiments/catdb-results/dataset_2_rnc/gpt-4/dataset_2_rnc-MISSING_VALUE_NUMERIC_STATISTIC-Random-0-SHOT-gpt-4.py", line 117, in <module>
    test_data[column] = le.transform(test_data[column].astype(str))
                        ^^^^^^^^^^^^^^^^^^^^^^^^^^^^^^^^^^^^^^^^^^^
  File "/home/ubuntu/CatDB/Experiments/catdb-results/dataset_2_rnc/gpt-4/venv/lib/python3.11/site-packages/sklearn/preprocessing/_label.py", line 137, in transform
    return _encode(y, uniques=self.classes_)
           ^^^^^^^^^^^^^^^^^^^^^^^^^^^^^^^^^
  File "/home/ubuntu/CatDB/Experiments/catdb-results/dataset_2_rnc/gpt-4/venv/lib/python3.11/site-packages/sklearn/utils/_encode.py", line 227, in _encode
    raise ValueError(f"y contains previously unseen labels: {str(e)}")
ValueError: y contains previously unseen labels: "'<0'"
