Traceback (most recent call last):
  File "/home/ubuntu/CatDB/Experiments/catdb-results/dataset_2_rnc/gpt-4/dataset_2_rnc-MISSING_VALUE-Random-0-SHOT-gpt-4.py", line 41, in <module>
    le = le_dict[col]
         ~~~~~~~^^^^^
KeyError: 'c_19'
